Workbook

Sheet Скач.Табл. 2022 ДТП
A1: Место | B1: Регион | C1: Количество ДТП с пострадавшими на 100 тыс. ед. автотранспорта в январе-июне 2022 г. | D1: Изменение количества ДТП с пострадавшими по сранению с январем-июнем 2021 г., % | E1: Число пострадавших (погибших и раненых) в ДТП на 100 тыс. жителей в январе-июне 2022 г.
A2: 66 | B2: Ярославская область | C2: 120.3 | D2: -19.4 | E2: 59.6
A3: 2 | B3: Ямало-Ненецкий автономный округ | C3: 44.2 | D3: 4.6 | E3: 27.2
A4: 14 | B4: Чукотский автономный округ | C4: 74.3 | D4: 28.6 | E4: 22
A5: 74 | B5: Чувашская Республика | C5: 127.7 | D5: -7.4 | E5: 51.9
A6: 1 | B6: Чеченская Республика | C6: 15.6 | D6: -42.2 | E6: 6
A7: 42 | B7: Челябинская область | C7: 99.6 | D7: -4.7 | E7: 56.5
A8: 9 | B8: Ханты-Мансийский автономный округ — Югра | C8: 64.4 | D8: -5.3 | E8: 49.1
A9: 63 | B9: Хабаровский край | C9: 114.9 | D9: -12.5 | E9: 59
A10: 34 | B10: Ульяновская область | C10: 94 | D10: -15.2 | E10: 52.8
A11: 45 | B11: Удмуртская Республика | C11: 101.4 | D11: -16.6 | E11: 49.9
A12: 81 | B12: Тюменская область | C12: 152.3 | D12: -11.3 | E12: 95.5
A13: 43 | B13: Тульская область | C13: 101.2 | D13: -6.7 | E13: 68.7
... A86: 41 | B86: Алтайский край | C86: 99.6 | D86: -4.1 | E86: 57.4

Sheet Передел. Скач.Табл. 2022 ДТП
A1: Регион | B1: Количество ДТП с пострадавшими на 100 тыс. ед. автотранспорта в январе-июне 2022 г.
A2: Ярославская область | B2: 120.3
A3: Ямало-Ненецкий автономный округ | B3: 44.2
A4: Чукотский автономный округ | B4: 74.3
A5: Чувашская Республика | B5: 127.7
A6: Чеченская Республика | B6: 15.6
A7: Челябинская область | B7: 99.6
A8: Ханты-Мансийский автономный округ — Югра | B8: 64.4
A9: Хабаровский край | B9: 114.9
A10: Ульяновская область | B10: 94
A11: Удмуртская Республика | B11: 101.4
A12: Тюменская область | B12: 152.3
A13: Тульская область | B13: 101.2
... A86: Алтайский край | B86: 99.6

Sheet Дин.Скач.ДТП2019
A1: Место | B1: Субъект РФ | C1: Количество ДТП с пострадавшими на 100 тысяч автомобилей в 2019 году | D1: Изменение количества ДТП с пострадавшими по сравнению с 2018 г., % | E1: Число пострадавших в ДТП (погибших и раненых) на 100 тысяч человек в 2019 году | F1: Число погибших на 1000 пострадавших в 2019 году
A2: 84 | B2: Ярославская область | C2: 504 | D2: 4.8 | E2: 228 | F2: 58
A3: 6 | B3: Ямало-Ненецкий автономный округ | C3: 183 | D3: -9.2 | E3: 109 | F3: 59
A4: 2 | B4: Чукотский автономный округ | C4: 139 | D4: -50 | E4: 36 | F4: 56
A5: 59 | B5: Чувашская Республика | C5: 363 | D5: -1.1 | E5: 145 | F5: 75
A6: 1 | B6: Чеченская Республика | C6: 76 | D6: 14.5 | E6: 34 | F6: 251
A7: 40 | B7: Челябинская область | C7: 322 | D7: 0 | E7: 173 | F7: 67
A8: 14 | B8: Ханты-Мансийский автономный округ — Югра | C8: 212 | D8: -2.3 | E8: 150 | F8: 66
A9: 74 | B9: Хабаровский край | C9: 415 | D9: -2.6 | E9: 194 | F9: 58
A10: 28 | B10: Ульяновская область | C10: 293 | D10: -3.9 | E10: 151 | F10: 94
A11: 66 | B11: Удмуртская Республика | C11: 397 | D11: 4.6 | E11: 191 | F11: 63
A12: 80 | B12: Тюменская область | C12: 455 | D12: 0 | E12: 265 | F12: 44
A13: 41 | B13: Тульская область | C13: 322 | D13: -3.6 | E13: 213 | F13: 88
... A86: 31 | B86: Алтайский край | C86: 304 | D86: -3.6 | E86: 164 | F86: 66

Sheet Редач.Дин.ДТП2019
A1: Субъект РФ | B1: Количество ДТП с пострадавшими на 100 тысяч автомобилей в 2019 году
A2: Ярославская область | B2: 504
A3: Ямало-Ненецкий автономный округ | B3: 183
A4: Чукотский автономный округ | B4: 139
A5: Чувашская Республика | B5: 363
A6: Чеченская Республика | B6: 76
A7: Челябинская область | B7: 322
A8: Ханты-Мансийский автономный округ — Югра | B8: 212
A9: Хабаровский край | B9: 415
A10: Ульяновская область | B10: 293
A11: Удмуртская Республика | B11: 397
A12: Тюменская область | B12: 455
A13: Тульская область | B13: 322
... A86: Алтайский край | B86: 304

Sheet ВосстРедач.Дин.ДТП2018
A1: Субъект РФ | B1: Количество ДТП с пострадавшими на 100 тысяч автомобилей в 2019 году | C1: Изменение количества ДТП с пострадавшими по сравнению с 2018 г., % | D1: Количество ДТП с пострадавшими на 100 тысяч автомобилей в 2018 году
A2: Ярославская область | B2: 504 | C2: 4.8 | D2: =B2*(1+C2/100) -> 528.192
A3: Ямало-Ненецкий автономный округ | B3: 183 | C3: -9.2 | D3: =B3*(1+C3/100) -> 166.164
A4: Чукотский автономный округ | B4: 139 | C4: -50 | D4: =B4*(1+C4/100) -> 69.5
A5: Чувашская Республика | B5: 363 | C5: -1.1 | D5: =B5*(1+C5/100) -> 359.007
A6: Чеченская Республика | B6: 76 | C6: 14.5 | D6: =B6*(1+C6/100) -> 87.02
A7: Челябинская область | B7: 322 | C7: 0 | D7: =B7*(1+C7/100) -> 322
A8: Ханты-Мансийский автономный округ — Югра | B8: 212 | C8: -2.3 | D8: =B8*(1+C8/100) -> 207.124
A9: Хабаровский край | B9: 415 | C9: -2.6 | D9: =B9*(1+C9/100) -> 404.21
A10: Ульяновская область | B10: 293 | C10: -3.9 | D10: =B10*(1+C10/100) -> 281.573
A11: Удмуртская Республика | B11: 397 | C11: 4.6 | D11: =B11*(1+C11/100) -> 415.262
A12: Тюменская область | B12: 455 | C12: 0 | D12: =B12*(1+C12/100) -> 455
A13: Тульская область | B13: 322 | C13: -3.6 | D13: =B13*(1+C13/100) -> 310.408
... A86: Алтайский край | B86: 304 | C86: -3.6 | D86: =B86*(1+C86/100) -> 293.056

Sheet Редач.Дин.ДТП2020
A1: Регион | B1: Количество ДТП с пострадавшими на 100 тысяч автомобилей в январе-сентябре 2020 г.
A2: Ярославская область | B2: 297
A3: Ямало-Ненецкий автономный округ | B3: 112
A4: Чукотский автономный округ | B4: 147
A5: Чувашская Республика | B5: 250
A6: Чеченская Республика | B6: 44
A7: Челябинская область | B7: 208
A8: Ханты-Мансийский автономный округ — Югра | B8: 122
A9: Хабаровский край | B9: 255
A10: Ульяновская область | B10: 194
A11: Удмуртская Республика | B11: 267
A12: Тюменская область | B12: 284
A13: Тульская область | B13: 201
... A86: Алтайский край | B86: 207

Sheet Дин.Скач.ДТП2020
A1: Место | B1: Регион | C1: Количество ДТП с пострадавшими на 100 тысяч автомобилей в январе-сентябре 2020 г. | D1: Изменение количества ДТП с пострадавшими по сравнению с январем-сентябрем 2019 г., % | E1: Число пострадавших в ДТП (погибших и раненых) на 100 тысяч жителей в январе-сентябре 2020 г. | F1: Число погибших в ДТП на 1 тыс. пострадавших
A2: 80 | B2: Ярославская область | C2: 297 | D2: -16.6 | E2: 136 | F2: 71
A3: 6 | B3: Ямало-Ненецкий автономный округ | C3: 112 | D3: -13.5 | E3: 67 | F3: 85
A4: 15 | B4: Чукотский автономный округ | C4: 147 | D4: 54.5 | E4: 36 | F4: 222
A5: 63 | B5: Чувашская Республика | C5: 250 | D5: -4.7 | E5: 98 | F5: 73
A6: 1 | B6: Чеченская Республика | C6: 44 | D6: -6.2 | E6: 18 | F6: 264
A7: 39 | B7: Челябинская область | C7: 208 | D7: -6.5 | E7: 110 | F7: 65
A8: 8 | B8: Ханты-Мансийский автономный округ — Югра | C8: 122 | D8: -13.8 | E8: 86 | F8: 75
A9: 65 | B9: Хабаровский край | C9: 255 | D9: -14.2 | E9: 128 | F9: 73
A10: 30 | B10: Ульяновская область | C10: 194 | D10: -5.6 | E10: 98 | F10: 75
A11: 71 | B11: Удмуртская Республика | C11: 267 | D11: -1.5 | E11: 129 | F11: 59
A12: 77 | B12: Тюменская область | C12: 284 | D12: -14.9 | E12: 175 | F12: 54
A13: 32 | B13: Тульская область | C13: 201 | D13: -12.2 | E13: 131 | F13: 90
... A86: 36 | B86: Алтайский край | C86: 207 | D86: -7 | E86: 111 | F86: 65

Sheet ВосстРедач.Дин.ДТП2021
A1: Регион | B1: Количество ДТП с пострадавшими на 100 тыс. ед. автотранспорта в январе-июне 2022 г. | C1: Изменение количества ДТП с пострадавшими по сранению с январем-июнем 2021 г., % | D1: Количество ДТП с пострадавшими на 100 тыс. ед. автотранспорта в январе-июне 2021 г.
A2: Ярославская область | B2: 120.3 | C2: -19.4 | D2: =B2*(1+C2:C2/100) -> 96.9618
A3: Ямало-Ненецкий автономный округ | B3: 44.2 | C3: 4.6 | D3: =B3*(1+C3:C3/100) -> 46.2332
A4: Чукотский автономный округ | B4: 74.3 | C4: 28.6 | D4: =B4*(1+C4:C4/100) -> 95.5498
A5: Чувашская Республика | B5: 127.7 | C5: -7.4 | D5: =B5*(1+C5:C5/100) -> 118.2502
A6: Чеченская Республика | B6: 15.6 | C6: -42.2 | D6: =B6*(1+C6:C6/100) -> 9.0168
A7: Челябинская область | B7: 99.6 | C7: -4.7 | D7: =B7*(1+C7:C7/100) -> 94.9188
A8: Ханты-Мансийский автономный округ — Югра | B8: 64.4 | C8: -5.3 | D8: =B8*(1+C8:C8/100) -> 60.9868
A9: Хабаровский край | B9: 114.9 | C9: -12.5 | D9: =B9*(1+C9:C9/100) -> 100.5375
A10: Ульяновская область | B10: 94 | C10: -15.2 | D10: =B10*(1+C10:C10/100) -> 79.712
A11: Удмуртская Республика | B11: 101.4 | C11: -16.6 | D11: =B11*(1+C11:C11/100) -> 84.5676
A12: Тюменская область | B12: 152.3 | C12: -11.3 | D12: =B12*(1+C12:C12/100) -> 135.0901
A13: Тульская область | B13: 101.2 | C13: -6.7 | D13: =B13*(1+C13:C13/100) -> 94.4196
... A86: Алтайский край | B86: 99.6 | C86: -4.1 | D86: =B86*(1+C86:C86/100) -> 95.5164

Sheet Дин.Скач.ДТП2023
A1: Место | B1: Регион | C1: Количество ДТП с пострадавшими на 100 тыс. автомобилей в январе-июне 2023 г. | D1: Изменение количества ДТП с пострадавшими по сранению с январем-июнем 2022 г., % | E1: Число пострадавших в ДТП (погибших и раненых) в ДТП на 100 тыс. жителей в январе-июне 2023 г.
A2: 71 | B2: Ярославская область | C2: 131 | D2: 9.2 | E2: 70.1
A3: 3 | B3: Ямало-Ненецкий автономный округ | C3: 41.5 | D3: -5.3 | E3: 28.1
A4: 6 | B4: Чукотский автономный округ | C4: 56 | D4: -22.2 | E4: 25.1
A5: 57 | B5: Чувашская Республика | C5: 113.9 | D5: -10 | E5: 49.8
A6: 1 | B6: Чеченская Республика | C6: 13.8 | D6: -5.1 | E6: 6.5
A7: 36 | B7: Челябинская область | C7: 99.4 | D7: 3.2 | E7: 57.4
A8: 9 | B8: Ханты-Мансийский автономный округ – Югра | C8: 59.8 | D8: -4.8 | E8: 45
A9: 55 | B9: Хабаровский край | C9: 113 | D9: -0.9 | E9: 58.3
A10: 34 | B10: Ульяновская область | C10: 96.8 | D10: 2.4 | E10: 51.1
A11: 50 | B11: Удмуртская Республика | C11: 111.1 | D11: 7.2 | E11: 50.7
A12: 82 | B12: Тюменская область | C12: 185.9 | D12: 22.6 | E12: 108.6
A13: 47 | B13: Тульская область | C13: 107.5 | D13: 5 | E13: 72.8
... A86: 33 | B86: Алтайский край | C86: 96.7 | D86: -3.2 | E86: 57.2

Sheet Редач.Дин.ДТП2023
A1: Регион | B1: Количество ДТП с пострадавшими на 100 тыс. автомобилей в январе-июне 2023 г.
A2: Ярославская область | B2: 131
A3: Ямало-Ненецкий автономный округ | B3: 41.5
A4: Чукотский автономный округ | B4: 56
A5: Чувашская Республика | B5: 113.9
A6: Чеченская Республика | B6: 13.8
A7: Челябинская область | B7: 99.4
A8: Ханты-Мансийский автономный округ – Югра | B8: 59.8
A9: Хабаровский край | B9: 113
A10: Ульяновская область | B10: 96.8
A11: Удмуртская Республика | B11: 111.1
A12: Тюменская область | B12: 185.9
A13: Тульская область | B13: 107.5
... A86: Алтайский край | B86: 96.7

Sheet Скачанные таблицы 2024 ДТП Плот
B2: Место | C2: Регион | D2: Количество ДТП с пострадавшими на 100 тыс. ед. автотранспорта в январе-июне 2024 г. | E2: Изменение количества ДТП с пострадавшими по сранению с январем-июнем 2023 г., % | F2: Число пострадавших (погибших и раненых) в ДТП на 100 тыс. жителей в январе-июне 2024 г. | H2: Место | I2: Регион | J2: Доля автомобильных дорог общего пользования регионального или межмуниципального значения и местного значения, отвечающих нормативным требованиям, в общей протяженности соответствующих дорог на конец 2023 года, % | K2: Плотность автомобильных дорог общего пользования с твердым покрытием, километров дорог на 1000 км² территории
B3: 74 | C3: Ярославская область | D3: 133.3 | E3: 2.2 | F3: 72.3 | H3: 79 | I3: Ярославская область | J3: 37.2 | K3: 287.1
B4: 2 | C4: Ямало-Ненецкий автономный округ | D4: 42.5 | E4: 6.5 | F4: 28.5 | H4: 8 | I4: Ямало-Ненецкий автономный округ | J4: 74.9 | K4: 3.7
B5: 3 | C5: Чукотский автономный округ | D5: 46.7 | E5: -14.3 | F5: 25 | H5: 14 | I5: Чукотский автономный округ | J5: 71.3 | K5: 1.3
B6: 35 | C6: Чувашская Республика | D6: 95.1 | E6: -15.7 | F6: 41.9 | H6: 77 | I6: Чувашская Республика | J6: 37.3 | K6: 471.7
B7: 1 | C7: Чеченская Республика | D7: 11.1 | E7: -10.7 | F7: 5.2 | H7: 45 | I7: Чеченская Республика | J7: 52.2 | K7: 651.7
B8: 38 | C8: Челябинская область | D8: 96.7 | E8: 2.2 | F8: 59.3 | H8: 4 | I8: Челябинская область | J8: 84.1 | K8: 248.6
B9: - | C9: Херсонская область | D9: Н/Д | E9: Н/Д | F9: Н/Д | H9: - | I9: Херсонская область | J9: Н/Д | K9: Н/Д
B10: 7 | C10: Ханты-Мансийский автономный округ — Югра | D10: 53.9 | E10: -6.2 | F10: 43.3 | H10: 2 | I10: Ханты-Мансийский автономный округ — Югра | J10: 88.4 | K10: 11.7
B11: 52 | C11: Хабаровский край | D11: 110.7 | E11: -0.9 | F11: 59.9 | H11: 13 | I11: Хабаровский край | J11: 71.4 | K11: 12.8
B12: 28 | C12: Ульяновская область | D12: 88.1 | E12: -9 | F12: 49.5 | H12: 31 | I12: Ульяновская область | J12: 59.7 | K12: 262.6
B13: 55 | C13: Удмуртская Республика | D13: 112.8 | E13: 2.1 | F13: 54 | H13: 69 | I13: Удмуртская Республика | J13: 41.9 | K13: 269.6
B14: 82 | C14: Тюменская область | D14: 176.8 | E14: -1.5 | F14: 106.2 | H14: 12 | I14: Тюменская область | J14: 72.8 | K14: 93.2
B15: 49 | C15: Тульская область | D15: 108.6 | E15: 1 | F15: 67 | H15: 41 | I15: Тульская область | J15: 53.9 | K15: 413.1
B16: 5 | C16: Томская область | D16: 49.4 | E16: 24.7 | F16: 24.9 | H16: 40 | I16: Томская область | J16: 54.5 | K16: 25.6
B17: 48 | C17: Тверская область | D17: 108.4 | E17: 3.1 | F17: 71.3 | H17: 28 | I17: Тверская область | J17: 60.7 | K17: 257.5
B18: 43 | C18: Тамбовская область | D18: 104.1 | E18: 2.6 | F18: 75.7 | H18: 74 | I18: Тамбовская область | J18: 39.3 | K18: 299.2
B19: 62 | C19: Ставропольский край | D19: 118.1 | E19: 2.7 | F19: 53.1 | H19: 19 | I19: Ставропольский край | J19: 65 | K19: 280.7
B20: 59 | C20: Смоленская область | D20: 116.4 | E20: -18.2 | F20: 53 | H20: 66 | I20: Смоленская область | J20: 43.4 | K20: 336.6
B21: 71 | C21: Севастополь | D21: 125.8 | E21: -17.5 | F21: 50.2 | H21: 9 | I21: Севастополь | J21: 74.8 | K21: 1213.5
... B60: 32 | C60: Магаданская область | D60: 89.9 | E60: -9.2 | F60: 78 | H60: 77 | I60: Магаданская область | J60: 37.3 | K60: 5.6
B61: - | C61: Луганская Народная Республика | D61: Н/Д | E61: Н/Д | F61: Н/Д | H61: - | I61: Луганская Народная Республика | J61: Н/Д | K61: Н/Д
B62: 23 | C62: Липецкая область | D62: 83.8 | E62: -12.6 | F62: 62.4 | H62: 23 | I62: Липецкая область | J62: 62.8 | K62: 567.4
B63: 42 | C63: Ленинградская область | D63: 99.1 | E63: -14.9 | F63: 48.1 | H63: 34 | I63: Ленинградская область | J63: 58.7 | K63: 221.7
B64: 69 | C64: Курская область | D64: 123.1 | E64: 16.4 | F64: 69.4 | H64: 55 | I64: Курская область | J64: 46.5 | K64: 384.3
B65: 25 | C65: Курганская область | D65: 85.8 | E65: -3.5 | F65: 57.4 | H65: 37 | I65: Курганская область | J65: 57.2 | K65: 136.8
B66: 53 | C66: Красноярский край | D66: 111.1 | E66: 4.9 | F66: 57.4 | H66: 21 | I66: Красноярский край | J66: 64 | K66: 11.7
B67: 70 | C67: Краснодарский край | D67: 124.1 | E67: 3.1 | F67: 61.3 | H67: 3 | I67: Краснодарский край | J67: 84.4 | K67: 481
B68: 81 | C68: Костромская область | D68: 171.2 | E68: 13.5 | F68: 91.5 | H68: 51 | I68: Костромская область | J68: 48.3 | K68: 139.3
B69: 79 | C69: Кировская область | D69: 166.4 | E69: 6.7 | F69: 79.5 | H69: 84 | I69: Кировская область | J69: 26.3 | K69: 115.8
B70: 34 | C70: Кемеровская область | D70: 93 | E70: -6.4 | F70: 58.9 | H70: 15 | I70: Кемеровская область | J70: 71.2 | K70: 183.1
B71: 66 | C71: Карачаево-Черкесская Республика | D71: 122.8 | E71: -18.6 | F71: 50.2 | H71: 58 | I71: Карачаево-Черкесская Республика | J71: 45.4 | K71: 363.3
B72: 27 | C72: Камчатский край | D72: 87.2 | E72: 28.4 | F72: 81 | H72: 42 | I72: Камчатский край | J72: 53.4 | K72: 4.4
B73: 72 | C73: Калужская область | D73: 127.1 | E73: 1.3 | F73: 62 | H73: 47 | I73: Калужская область | J73: 51.4 | K73: 365.4
... B77: 56 | C77: Ивановская область | D77: 113.7 | E77: 5.8 | F77: 72.3 | H77: 36 | I77: Ивановская область | J77: 57.3 | K77: 338.4
B78: - | C78: Запорожская область | D78: Н/Д | E78: Н/Д | F78: Н/Д | H78: - | I78: Запорожская область | J78: Н/Д | K78: Н/Д
B79: 40 | C79: Забайкальский край | D79: 97.9 | E79: -2.6 | F79: 53.7 | H79: 56 | I79: Забайкальский край | J79: 46.1 | K79: 34.9
B80: 68 | C80: Еврейская автономная область | D80: 123.1 | E80: -18.2 | F80: 67.2 | H80: 70 | I80: Еврейская автономная область | J80: 41.4 | K80: 71.2
B81: - | C81: Донецкая Народная Республика | D81: Н/Д | E81: Н/Д | F81: Н/Д | H81: - | I81: Донецкая Народная Республика | J81: Н/Д | K81: Н/Д
B82: 54 | C82: Воронежская область | D82: 111.7 | E82: -0.4 | F82: 68.7 | H82: 38 | I82: Воронежская область | J82: 56.7 | K82: 429.3
...

Sheet Переделанная таблица 2024
B2: Регион | C2: Количество ДТП с пострадавшими на 100 тыс. ед. автотранспорта в январе-июне 2024 г. | D2: Число пострадавших (погибших и раненых) в ДТП на 100 тыс. жителей в январе-июне 2024 г. | E2: Доля автомобильных дорог общего пользования регионального или межмуниципального значения и местного значения, отвечающих нормативным требованиям, в общей протяженности соответствующих дорог на конец 2023 года, % | F2: Плотность автомобильных дорог общего пользования с твердым покрытием, километров дорог на 1000 км² территории
B3: Ярославская область | C3: 133.3 | D3: 72.3 | E3: 37.2 | F3: 287.1
B4: Ямало-Ненецкий автономный округ | C4: 42.5 | D4: 28.5 | E4: 74.9 | F4: 3.7
B5: Чукотский автономный округ | C5: 46.7 | D5: 25 | E5: 71.3 | F5: 1.3
B6: Чувашская Республика | C6: 95.1 | D6: 41.9 | E6: 37.3 | F6: 471.7
B7: Чеченская Республика | C7: 11.1 | D7: 5.2 | E7: 52.2 | F7: 651.7
B8: Челябинская область | C8: 96.7 | D8: 59.3 | E8: 84.1 | F8: 248.6
B9: Херсонская область | C9: Н/Д | D9: Н/Д | E9: Н/Д | F9: Н/Д
B10: Ханты-Мансийский автономный округ — Югра | C10: 53.9 | D10: 43.3 | E10: 88.4 | F10: 11.7
B11: Хабаровский край | C11: 110.7 | D11: 59.9 | E11: 71.4 | F11: 12.8
B12: Ульяновская область | C12: 88.1 | D12: 49.5 | E12: 59.7 | F12: 262.6
B13: Удмуртская Республика | C13: 112.8 | D13: 54 | E13: 41.9 | F13: 269.6
B14: Тюменская область | C14: 176.8 | D14: 106.2 | E14: 72.8 | F14: 93.2
B15: Тульская область | C15: 108.6 | D15: 67 | E15: 53.9 | F15: 413.1
B16: Томская область | C16: 49.4 | D16: 24.9 | E16: 54.5 | F16: 25.6
B17: Тверская область | C17: 108.4 | D17: 71.3 | E17: 60.7 | F17: 257.5
B18: Тамбовская область | C18: 104.1 | D18: 75.7 | E18: 39.3 | F18: 299.2
B19: Ставропольский край | C19: 118.1 | D19: 53.1 | E19: 65 | F19: 280.7
B20: Смоленская область | C20: 116.4 | D20: 53 | E20: 43.4 | F20: 336.6
B21: Севастополь | C21: 125.8 | D21: 50.2 | E21: 74.8 | F21: 1213.5
... B60: Магаданская область | C60: 89.9 | D60: 78 | E60: 37.3 | F60: 5.6
B61: Луганская Народная Республика | C61: Н/Д | D61: Н/Д | E61: Н/Д | F61: Н/Д
B62: Липецкая область | C62: 83.8 | D62: 62.4 | E62: 62.8 | F62: 567.4
B63: Ленинградская область | C63: 99.1 | D63: 48.1 | E63: 58.7 | F63: 221.7
B64: Курская область | C64: 123.1 | D64: 69.4 | E64: 46.5 | F64: 384.3
B65: Курганская область | C65: 85.8 | D65: 57.4 | E65: 57.2 | F65: 136.8
B66: Красноярский край | C66: 111.1 | D66: 57.4 | E66: 64 | F66: 11.7
B67: Краснодарский край | C67: 124.1 | D67: 61.3 | E67: 84.4 | F67: 481
B68: Костромская область | C68: 171.2 | D68: 91.5 | E68: 48.3 | F68: 139.3
B69: Кировская область | C69: 166.4 | D69: 79.5 | E69: 26.3 | F69: 115.8
B70: Кемеровская область | C70: 93 | D70: 58.9 | E70: 71.2 | F70: 183.1
B71: Карачаево-Черкесская Республика | C71: 122.8 | D71: 50.2 | E71: 45.4 | F71: 363.3
B72: Камчатский край | C72: 87.2 | D72: 81 | E72: 53.4 | F72: 4.4
B73: Калужская область | C73: 127.1 | D73: 62 | E73: 51.4 | F73: 365.4
... B77: Ивановская область | C77: 113.7 | D77: 72.3 | E77: 57.3 | F77: 338.4
B78: Запорожская область | C78: Н/Д | D78: Н/Д | E78: Н/Д | F78: Н/Д
B79: Забайкальский край | C79: 97.9 | D79: 53.7 | E79: 46.1 | F79: 34.9
B80: Еврейская автономная область | C80: 123.1 | D80: 67.2 | E80: 41.4 | F80: 71.2
B81: Донецкая Народная Республика | C81: Н/Д | D81: Н/Д | E81: Н/Д | F81: Н/Д
B82: Воронежская область | C82: 111.7 | D82: 68.7 | E82: 56.7 | F82: 429.3
...

Sheet Рабочая таблица 2024
B2: Регион | C2: Количество ДТП с пострадавшими на 100 тыс. ед. автотранспорта в январе-июне 2024 г. | D2: Число пострадавших (погибших и раненых) в ДТП на 100 тыс. жителей в январе-июне 2024 г. | E2: Доля автомобильных дорог общего пользования регионального или межмуниципального значения и местного значения, отвечающих нормативным требованиям, в общей протяженности соответствующих дорог на конец 2023 года, % | F2: Плотность автомобильных дорог общего пользования с твердым покрытием, километров дорог на 1000 км² территории | G2: К какому Федеральному округу принадлежит
B3: Ярославская область | C3: 133.3 | D3: 72.3 | E3: 37.2 | F3: 287.1 | G3: Центральный федеральный округ
B4: Ямало-Ненецкий автономный округ | C4: 42.5 | D4: 28.5 | E4: 74.9 | F4: 3.7 | G4: Уральский федеральный округ
B5: Чукотский автономный округ | C5: 46.7 | D5: 25 | E5: 71.3 | F5: 1.3 | G5: Дальневосточный федеральный округ
B6: Чувашская Республика | C6: 95.1 | D6: 41.9 | E6: 37.3 | F6: 471.7 | G6: Приволжский федеральный округ
B7: Чеченская Республика | C7: 11.1 | D7: 5.2 | E7: 52.2 | F7: 651.7 | G7: Южный федеральный округ
B8: Челябинская область | C8: 96.7 | D8: 59.3 | E8: 84.1 | F8: 248.6 | G8: Уральский федеральный округ
B9: Ханты-Мансийский автономный округ — Югра | C9: 53.9 | D9: 43.3 | E9: 88.4 | F9: 11.7 | G9: Уральский федеральный округ
B10: Хабаровский край | C10: 110.7 | D10: 59.9 | E10: 71.4 | F10: 12.8 | G10: Дальневосточный федеральный округ
B11: Ульяновская область | C11: 88.1 | D11: 49.5 | E11: 59.7 | F11: 262.6 | G11: Приволжский федеральный округ
B12: Удмуртская Республика | C12: 112.8 | D12: 54 | E12: 41.9 | F12: 269.6 | G12: Приволжский федеральный округ
B13: Тюменская область | C13: 176.8 | D13: 106.2 | E13: 72.8 | F13: 93.2 | G13: Уральский федеральный округ
B14: Тульская область | C14: 108.6 | D14: 67 | E14: 53.9 | F14: 413.1 | G14: Центральный федеральный округ
... B87: Алтайский край | C87: 105.4 | D87: 65.7 | E87: 36.3 | F87: 199.8 | G87: Сибирский федеральный округ

Sheet ДиспАнДТП
A3: Названия строк | B3: Количество по полю Количество ДТП с пострадавшими на 100 тыс. ед. автотранспорта в январе-июне 2024 г. | C3: Среднее по полю Количество ДТП с пострадавшими на 100 тыс. ед. автотранспорта в январе-июне 2024 г.2 | D3: Смещенная дисперсия по полю Количество ДТП с пострадавшими на 100 тыс. ед. автотранспорта в январе-июне 2024 г.3
A4: Дальневосточный федеральный округ | B4: 10 | C4: 100.76 | D4: 996.88044
A5: Приволжский федеральный округ | B5: 14 | C5: 103.94286 | D5: 1018.8134
A6: Северо-Западный федеральный округ | B6: 11 | C6: 96.390909 | D6: 383.68091
A7: Сибирский федеральный округ | B7: 11 | C7: 124.26364 | D7: 3476.8325
A8: Уральский федеральный округ | B8: 6 | C8: 84.7 | D8: 2478.788
A9: Центральный федеральный округ | B9: 18 | C9: 107.57222 | D9: 927.54095
A10: Южный федеральный округ | B10: 15 | C10: 104.23333 | D10: 2004.8095
A11: Общий итог | B11: 85 | C11: 104.68235 | D11: 1484.9481
A16: Факторный признак | B16: Количество по полю Количество ДТП с пострадавшими на 100 тыс. ед. автотранспорта в январе-июне 2024 г. | C16: Среднее по полю Количество ДТП с пострадавшими на 100 тыс. ед. автотранспорта в январе-июне 2024 г.2 | D16: Смещенная дисперсия по полю Количество ДТП с пострадавшими на 100 тыс. ед. автотранспорта в январе-июне 2024 г.3 | E16: Межгрупповая дисперсия | F16: Внутригрупповая дисперсия
A17: Дальневосточный федеральный округ | B17: 10 | C17: 100.76 | D17: 996.88044 | E17: =POWER(C17-$C$24,2)*B17/$B$24 -> 1.8099827 | F17: =D17*B17/$B$24 -> 117.28005
A18: Приволжский федеральный округ | B18: 14 | C18: 103.94286 | D18: 1018.8134 | E18: =POWER(C18-$C$24,2)*B18/$B$24 -> 0.090070076 | F18: =D18*B18/$B$24 -> 167.80456
A19: Северо-Западный федеральный округ | B19: 11 | C19: 96.390909 | D19: 383.68091 | E19: =POWER(C19-$C$24,2)*B19/$B$24 -> 8.8968053 | F19: =D19*B19/$B$24 -> 49.652824
A20: Сибирский федеральный округ | B20: 11 | C20: 124.26364 | D20: 3476.8325 | E20: =POWER(C20-$C$24,2)*B20/$B$24 -> 49.619921 | F20: =D20*B20/$B$24 -> 449.94304
A21: Уральский федеральный округ | B21: 6 | C21: 84.7 | D21: 2478.788 | E21: =POWER(C21-$C$24,2)*B21/$B$24 -> 28.185489 | F21: =D21*B21/$B$24 -> 174.97327
A22: Центральный федеральный округ | B22: 18 | C22: 107.57222 | D22: 927.54095 | E22: =POWER(C22-$C$24,2)*B22/$B$24 -> 1.76852 | F22: =D22*B22/$B$24 -> 196.42044
A23: Южный федеральный округ | B23: 15 | C23: 104.23333 | D23: 2004.8095 | E23: =POWER(C23-$C$24,2)*B23/$B$24 -> 0.035579754 | F23: =D23*B23/$B$24 -> 353.78992
A24: Общий итог | B24: 85 | C24: 104.68235 | D24: 1484.9481 | E24: =SUM(E17:E23) -> 90.406368 | F24: =SUM(F17:F23) -> 1509.8641
A26: dсрвн | B26: =F24 -> 1509.8641 | I26: Правило сложения дисперсий
A27: б^2(межгрупповая дисперсия) | B27: =E24 -> 90.406368 | I27: =SUM(B26:B27) -> 1600.2705 | J27: = | K27: =B27 -> 90.406368 | L27: + | M27: =B26 -> 1509.8641
I28: =I27/I27 -> 1 | J28: = | K28: =K27/I27 -> 0.05649443 | L28: + | M28: =M27/I27 -> 0.94350557
B29: Вывод: | C29: <1/2 - качественный признак (федеральный округ) не влияет на число ДТП

Sheet ДиспАнПлотность
A3: Названия строк | B3: Количество по полю Плотность автомобильных дорог общего пользования с твердым покрытием, километров дорог на 1000 км² территории | C3: Среднее по полю Плотность автомобильных дорог общего пользования с твердым покрытием, километров дорог на 1000 км² территории2 | D3: Смещенная дисперсия по полю Плотность автомобильных дорог общего пользования с твердым покрытием, километров дорог на 1000 км² территории
A4: Дальневосточный федеральный округ | B4: 10 | C4: 29.84 | D4: 986.89156
A5: Приволжский федеральный округ | B5: 14 | C5: 277.91429 | D5: 11933.307
A6: Северо-Западный федеральный округ | B6: 11 | C6: 366.12727 | D6: 546201
A7: Сибирский федеральный округ | B7: 11 | C7: 78.218182 | D7: 4351.4316
A8: Уральский федеральный округ | B8: 6 | C8: 103.96667 | D8: 8269.3307
A9: Центральный федеральный округ | B9: 18 | C9: 518.86667 | D9: 278007.05
A10: Южный федеральный округ | B10: 15 | C10: 501.84 | D10: 107222.41
A11: Общий итог | B11: 85 | C11: 312.56471 | D11: 178029.36
B13: Факторный признак | C13: Количество по полю Плотность автомобильных дорог общего пользования с твердым покрытием, километров дорог на 1000 км² территории | D13: Среднее по полю Плотность автомобильных дорог общего пользования с твердым покрытием, километров дорог на 1000 км² территории | E13: Смещенная дисперсия по полю Плотность автомобильных дорог общего пользования с твердым покрытием, километров дорог на 1000 км² территории | F13: Межгрупповая дисперсия | G13: Внутригрупповая дисперсия
B14: Дальневосточный федеральный округ | C14: 10 | D14: 29.84 | E14: 986.89156 | F14: =POWER(D14-$D$21,2)*C14/$C$21 -> 9403.9129 | G14: =E14*C14/$C$21 -> 116.10489
B15: Приволжский федеральный округ | C15: 14 | D15: 277.91429 | E15: 11933.307 | F15: =POWER(D15-$D$21,2)*C15/$C$21 -> 197.75438 | G15: =E15*C15/$C$21 -> 1965.4859
B16: Северо-Западный федеральный округ | C16: 11 | D16: 366.12727 | E16: 546201 | F16: =POWER(D16-$D$21,2)*C16/$C$21 -> 371.2757 | G16: =E16*C16/$C$21 -> 70684.836
B17: Сибирский федеральный округ | C17: 11 | D17: 78.218182 | E17: 4351.4316 | F17: =POWER(D17-$D$21,2)*C17/$C$21 -> 7107.0733 | G17: =E17*C17/$C$21 -> 563.12645
B18: Уральский федеральный округ | C18: 6 | D18: 103.96667 | E18: 8269.3307 | F18: =POWER(D18-$D$21,2)*C18/$C$21 -> 3071.5159 | G18: =E18*C18/$C$21 -> 583.71746
B19: Центральный федеральный округ | C19: 18 | D19: 518.86667 | E19: 278007.05 | F19: =POWER(D19-$D$21,2)*C19/$C$21 -> 9012.8116 | G19: =E19*C19/$C$21 -> 58872.08
B20: Южный федеральный округ | C20: 15 | D20: 501.84 | E20: 107222.41 | F20: =POWER(D20-$D$21,2)*C20/$C$21 -> 6322.083 | G20: =E20*C20/$C$21 -> 18921.602
B21: Общий итог | C21: 85 | D21: 312.56471 | E21: 178029.36 | F21: =SUM(F14:F20) -> 35486.427 | G21: =SUM(G14:G20) -> 151706.95
B23: dсрвн | C23: =G21 -> 151706.95 | J23: Правило сложения дисперсий
B24: б^2(межгрупповая дисперсия) | C24: =F21 -> 35486.427 | J24: =SUM(F21:G21) -> 187193.38 | K24: = | L24: =F21 -> 35486.427 | M24: + | N24: =G21 -> 151706.95
J25: =J24/J24 -> 1 | K25: = | L25: =L24/J24 -> 0.18957095 | M25: + | N25: =N24/J24 -> 0.81042905
B27: Вывод: | C27: <1/2 - качественный признак (федеральный округ) не влияет на уровень плотности дорог

Sheet Таблица с одним кач и двумя кол
B2: Регион | C2: Количество ДТП с пострадавшими на 100 тыс. ед. автотранспорта в январе-июне 2024 г. | D2: Плотность автомобильных дорог общего пользования с твердым покрытием, километров дорог на 1000 км² территории | E2: К какому Федеральному округу принадлежит
B3: Ярославская область | C3: 133.3 | D3: 287.1 | E3: Центральный федеральный округ
B4: Ямало-Ненецкий автономный округ | C4: 42.5 | D4: 3.7 | E4: Уральский федеральный округ
B5: Чукотский автономный округ | C5: 46.7 | D5: 1.3 | E5: Дальневосточный федеральный округ
B6: Чувашская Республика | C6: 95.1 | D6: 471.7 | E6: Приволжский федеральный округ
B7: Чеченская Республика | C7: 11.1 | D7: 651.7 | E7: Южный федеральный округ
B8: Челябинская область | C8: 96.7 | D8: 248.6 | E8: Уральский федеральный округ
B9: Ханты-Мансийский автономный округ — Югра | C9: 53.9 | D9: 11.7 | E9: Уральский федеральный округ
B10: Хабаровский край | C10: 110.7 | D10: 12.8 | E10: Дальневосточный федеральный округ
B11: Ульяновская область | C11: 88.1 | D11: 262.6 | E11: Приволжский федеральный округ
B12: Удмуртская Республика | C12: 112.8 | D12: 269.6 | E12: Приволжский федеральный округ
B13: Тюменская область | C13: 176.8 | D13: 93.2 | E13: Уральский федеральный округ
B14: Тульская область | C14: 108.6 | D14: 413.1 | E14: Центральный федеральный округ
... B87: Алтайский край | C87: 105.4 | D87: 199.8 | E87: Сибирский федеральный округ

Sheet Груп. по кач. пр. 1, 2
A1: Группировочный признак (федеральный округ) | B1: Среднее по полю Количество ДТП с пострадавшими на 100 тыс. ед. автотранспорта в январе-июне 2024 г.
A2: Сибирский федеральный округ | B2: 124.26364
A3: Центральный федеральный округ | B3: 107.57222
A4: Южный федеральный округ | B4: 104.23333
A5: Приволжский федеральный округ | B5: 103.94286
A6: Дальневосточный федеральный округ | B6: 100.76
A7: Северо-Западный федеральный округ | B7: 96.390909
A8: Уральский федеральный округ | B8: 84.7
A9: Общий итог | B9: 104.68235
A28: Вывод: если сравнивать средние значения количества ДТП среди регионов в каждом федеральном округе за период январь-июнь 2024 года, то наибольшее среднее значение наблюдается в Сибирском федеральном округе, если говорить о Федеральном округе с минимальным среди всех федеральных округов средним числом ДТП, то им является Уральский федеральный округ.
A31: Группировочный признак (федеральный округ) | B31: Минимум по полю Количество ДТП с пострадавшими на 100 тыс. ед. автотранспорта в январе-июне 2024 г.
A32: Северо-Западный федеральный округ | B32: 66.7
A33: Приволжский федеральный округ | B33: 54.2
A34: Сибирский федеральный округ | B34: 49.4
A35: Центральный федеральный округ | B35: 49.2
A36: Дальневосточный федеральный округ | B36: 46.7
A37: Уральский федеральный округ | B37: 42.5
A38: Южный федеральный округ | B38: 11.1
A39: Общий итог | B39: 11.1
A61: Вывод: если искать федеральный округ с наименьшим числом ДТП за период январь-июнь 2024 года, то этим округом является Южный федеральный округ, в нем есть субъект Федерации, в котором число ДТП меньше, чем во всех регионах в том же округе, кроме того, по сравнению с другими федеральными округами, этот округ занимает позицию за период январь-июнь 2024 года. Если же говорить о федеральном округе, который занимает лидирующую позицию по наличию субъекта Федерации с минимальным числом ДТП среди всех городов того же федерального округа, то этим округом является Северо-Западный федеральный округ. Если говорить о федеральном округе, в котором один из субъектов Федерации имеет минимальное среди других регионов этого округа число ДТП, но при этом федеральный округ, к которому отгосится этот регион, имеет последнее место среди остальных федеральных округов - это Северо-Западный федеральный округ.
A62: Группировочный признак (федеральный округ) | B62: Максимум по полю Количество ДТП с пострадавшими на 100 тыс. ед. автотранспорта в январе-июне 2024 г.
A63: Сибирский федеральный округ | B63: 265.1
A64: Южный федеральный округ | B64: 219.4
A65: Уральский федеральный округ | B65: 176.8
A66: Центральный федеральный округ | B66: 171.2
A67: Дальневосточный федеральный округ | B67: 166.8
A68: Приволжский федеральный округ | B68: 166.4
A69: Северо-Западный федеральный округ | B69: 122.9
A70: Общий итог | B70: 265.1
A92: Вывод: федеральный округ, в котором есть регион, который, в отличие от других субъектов Федерации этого округа, по сравнению с ними имеет максимальное число ДТП за период январь-июнь 2024 года, и если сравнивать этот федеральный округ с другими федеральными округами, в которых также имеется информация о субъекте Федерации, в котором совершается максимальное число ДТП, опять же, в сравнении с другими регионами этого округа, то Сибирский федеральный округ занимает лидирующую позицию среди всех остальных федеральных округов. Регион-лидер среди других субъектов Федерации одного федерального округа по числу ДТП, но занимающий последнее место по федеральным округам - Северо-Западный федеральный округ.
A97: Группировочный признак (федеральный округ) | B97: Среднее по полю Плотность автомобильных дорог общего пользования с твердым покрытием, километров дорог на 1000 км² территории
A98: Центральный федеральный округ | B98: 518.86667
A99: Южный федеральный округ | B99: 501.84
A100: Северо-Западный федеральный округ | B100: 366.12727
A101: Приволжский федеральный округ | B101: 277.91429
A102: Уральский федеральный округ | B102: 103.96667
A103: Сибирский федеральный округ | B103: 78.218182
A104: Дальневосточный федеральный округ | B104: 29.84
A105: Общий итог | B105: 312.56471
A127: Вывод: федеральным округом, который занимает лидирующую позицию по среднему значению плотности дорог всех входящих в него субъектов Федерации, является Центральный федеральный округ, а федеральный округ, который имеет наименьшее среднее число плотности дорог среди всех своих регионов - Дальневосточный федеральный округ.
...

Sheet Груп. по кол. пр. 1, 2
A1: Диапазон значений количества ДТП с пострадавшими на 100 тыс. ед. автотранспорта в январе-июне 2024 г. | B1: Среднее по полю Плотность автомобильных дорог общего пользования с твердым покрытием, километров дорог на 1000 км² территории
A2: 11,1-51,1 | B2: 306.22
A3: 51,1-91,1 | B3: 422.22222
A4: 91,1-131,1 | B4: 278.1125
A5: 131,1-171,1 | B5: 263.275
A6: 171,1-211,1 | B6: 110.9
A7: 211,1-251,1 | B7: 51.3
A8: 251,1-291,1 | B8: 22.2
A9: Общий итог | B9: 312.56471
A29: Вывод: данные показывают корреляцию между плотностью автомобильных дорог и количеством ДТП с пострадавшими. Наблюдается тенденция к снижению плотности дорог при увеличении количества ДТП на 100 тысяч единиц автотранспорта. Максимальная плотность дорог (422 км на 1000 км²) наблюдается в диапазоне 51-91 ДТП на 100 тыс. ед. автотранспорта, а минимальная (22,2 км на 1000 км²) - в диапазоне 251-291 ДТП. Средняя плотность дорог составляет 312,56 км на 1000 км².
A35: Диапазон значений количества ДТП с пострадавшими на 100 тыс. ед. автотранспорта в январе-июне 2024 г. | B35: Минимум по полю Плотность автомобильных дорог общего пользования с твердым покрытием, километров дорог на 1000 км² территории
A36: 11,1-51,1 | B36: 1.3
A37: 51,1-91,1 | B37: 1.9
A38: 91,1-131,1 | B38: 4.1
A39: 131,1-171,1 | B39: 37.2
A40: 171,1-211,1 | B40: 93.2
A41: 211,1-251,1 | B41: 51.3
A42: 251,1-291,1 | B42: 22.2
A43: Общий итог | B43: 1.3
A60: Вывод: данные показывают обратную зависимость между минимальной плотностью автомобильных дорог общего пользования с твердым покрытием и количеством ДТП с пострадавшими за период январь-июнь 2024 года. Наименьшая плотность дорог (1,3 км на 1000 км²) наблюдается при наибольшем количестве ДТП (более 251 на 100 тыс. единиц автотранспорта). Плотность дорог возрастает с уменьшением числа ДТП, достигая максимума (93,2 км на 1000 км²) в диапазоне 171-211 ДТП. График визуализирует эту обратную корреляцию, демонстрируя рост минимальной плотности дорог при снижении числа ДТП.
A62: Диапазон значений количества ДТП с пострадавшими на 100 тыс. ед. автотранспорта в январе-июне 2024 г. | B62: Максимум по полю Плотность автомобильных дорог общего пользования с твердым покрытием, километров дорог на 1000 км² территории
A63: 11,1-51,1 | B63: 848.8
A64: 51,1-91,1 | B64: 2542.4
A65: 91,1-131,1 | B65: 1213.5
A66: 131,1-171,1 | B66: 716.9
A67: 171,1-211,1 | B67: 139.3
A68: 211,1-251,1 | B68: 51.3
A69: 251,1-291,1 | B69: 22.2
A70: Общий итог | B70: 2542.4
A89: Вывод: анализ данных показывает неравномерное распределение максимальной плотности автомобильных дорог общего пользования с твердым покрытием в зависимости от количества ДТП с пострадавшими на 100 тыс. единиц автотранспорта в январе-июне 2024 г. Наибольшая плотность (2542,4 км на 1000 км²) наблюдается в диапазоне 51-91 ДТП. Плотность уменьшается с ростом количества ДТП, достигая минимума (22,2 км на 1000 км²) в диапазоне 251-291 ДТП. График иллюстрирует эту закономерность, демонстрируя пиковое значение плотности дорог в диапазоне 51-91 ДТП и последующее её снижение.
A96: Диапазон значений плотности автомобильных дорог общего пользования с твердым покрытием, километров дорог на 1000 км² территории | B96: Среднее по полю Количество ДТП с пострадавшими на 100 тыс. ед. автотранспорта в январе-июне 2024 г.
A97: 1,3-201,3 | B97: 108.54146
A98: 201,3-401,3 | B98: 110.39167
A99: 401,3-601,3 | B99: 96.890909
A100: 601,3-801,3 | B100: 79.975
A101: 801,3-1001,3 | B101: 49.2
A102: 1001,3-1201,3 | B102: 65.6
A103: 1201,3-1401,3 | B103: 125.8
A104: 2401,3-2601,3 | B104: 86.05
A105: Общий итог | B105: 104.68235
...

Sheet РядДинамики
A1: Год | B1: t (значение разницы в годах по сравнению с началом 2018 года) | C1: Среднее по полю Количество ДТП с пострадавшими на 100 тыс. ед. автотранспорта | D1: Минимум по полю Количество ДТП с пострадавшими на 100 тыс. ед. автотранспорта | E1: Максимум по полю Количество ДТП с пострадавшими на 100 тыс. ед. автотранспорта в январе-июне 2024 г.
A2: 2018 | B2: 1 | C2: =AVERAGE(ВосстРедач.Дин.ДТП2018!D2:D86) -> 313.96845 | D2: =MIN(ВосстРедач.Дин.ДТП2018!D2:D86) -> 69.5 | E2: =MAX(ВосстРедач.Дин.ДТП2018!D2:D86) -> 799.656
A3: 2019 | B3: 2 | C3: =AVERAGE(Редач.Дин.ДТП2019!B2:B86) -> 322.16471 | D3: =MIN(Редач.Дин.ДТП2019!B2:B86) -> 76 | E3: =MAX(Редач.Дин.ДТП2019!B2:B86) -> 858
A4: 2020 | B4: 3 | C4: =AVERAGE(Редач.Дин.ДТП2020!B2:B86) -> 213.16471 | D4: =MIN(Редач.Дин.ДТП2020!B2:B86) -> 44 | E4: =MAX(Редач.Дин.ДТП2020!B2:B86) -> 632
A5: 2021 | B5: 4 | C5: =AVERAGE(ВосстРедач.Дин.ДТП2021!D2:D86) -> 94.682165 | D5: =MIN(ВосстРедач.Дин.ДТП2021!D2:D86) -> 9.0168 | E5: =MAX(ВосстРедач.Дин.ДТП2021!D2:D86) -> 212.16
A6: 2022 | B6: 5 | C6: =AVERAGE('Передел. Скач.Табл. 2022 ДТП'!B2:B86) -> 100.82471 | D6: =MIN('Передел. Скач.Табл. 2022 ДТП'!B2:B86) -> 15.6 | E6: =MAX('Передел. Скач.Табл. 2022 ДТП'!B2:B86) -> 240
A7: 2023 | B7: 6 | C7: =AVERAGE(Редач.Дин.ДТП2023!B2:B86) -> 106.62471 | D7: =MIN(Редач.Дин.ДТП2023!B2:B86) -> 13.8 | E7: =MAX(Редач.Дин.ДТП2023!B2:B86) -> 315.6
A8: 2024 | B8: 7 | C8: =AVERAGE('Рабочая таблица 2024'!C3:C87) -> 104.68235 | D8: =MIN('Рабочая таблица 2024'!C3:C87) -> 11.1 | E8: =MAX('Рабочая таблица 2024'!C3:C87) -> 265.1
A44: Вывод: в результате исследования рядов динамики, можно сделать вывод, что с 2019 года по 2021-й можно заметить снижение показателя среднего числа ДТП, рассчитанного по всех субъектам Федерации; с 2021 года по 2023 год наблюдается небольшой подъем показателя среднего числа ДТП, рассчитанного по всем регионам, но с 2023 года по 2024-й наблюдается снижение этого показателя, но количество совершенных ДТП так и не вернулось к показателям на 2022 год. Если говорить о том, в каком году в среднем по всем регионам совершалось больше всего ДТП в период с 2018 по 2024 годы, то можно говорить, что в 2019 году был пик по среднему числу совершенных ДТП за год по всем субъектам Федерации. В 2021 году наблюдается минимальное в рассматриваемом временном диапазоне по годам среднее значение совершенных ДТП, рассчитанного также по всем субъектам Федерации. В целом, график среднего количества ДТП демонстрирует значительное снижение с 313,9 в 2018 году до 104,6 в 2024 году. Это указывает на общую позитивную динамику в области безопасности дорожного движения. Наиболее резкое падение произошло в 2020-2021 годах.
A64: Вывод: график минимального количества ДТП также показывает тенденцию к снижению, хотя и менее выраженную, чем для среднего значения. Минимальное количество ДТП снизилось с 69,5 в 2018 году до 11,1 в 2024 году. Это говорит о том, что даже в регионах с наименьшим количеством аварий наблюдается положительная динамика.
A82: Вывод: Динамика максимального количества ДТП с трудом прогнозируема . Хотя в 2021 году наблюдается резкое снижение, в последующие годы происходит колебательное движение с относительно высокими значениями. Это говорит о том, что работа по снижению аварийности в регионе среди всех субъектов Федерации с наибольшим числом ДТП требует дополнительных усилий.
A84: Общий вывод: снижение количества ДТП неравномерно по годам. Наблюдаются периоды резкого снижения и периоды замедления или незначительного роста. Это может быть связано с различными факторами, такими как экономическая ситуация, изменения в законодательстве и в дорожно-транспортной инфраструктуре, а также сезонными факторами. Данные также свидетельствуют о положительной динамике в снижении количества ДТП с пострадавшими в целом, но требуют дальнейшего анализа для выявления причин колебаний и разработки более эффективных мер по улучшению безопасности дорожного движения, особенно в регионах с высоким уровнем аварийности.

Sheet РядДинамикиПродолжение
A1: Количество ДТП с пострадавшими на 100 тысяч автомобилей за год | B1: Абсолютный прирост | D1: Темпы роста | F1: Темпы прироста | H1: Год
B2: Δδ (значение абсолютного базисного прироста) | C2: Δц (значение абсолютного цепного прироста) | D2: Тδ (значение базисного роста) | E2: Тц (значение цепного роста) | F2: Тпрδ (значение базисного прироста) | G2: Тпрц (значение цепного прироста)
A3: 26687.318 | B3: - | C3: - | D3: - | E3: - | F3: - | G3: - | H3: 2018
A4: 27384 | B4: =A4-$A$3 -> 696.682 | C4: =A4-A3 -> 696.682 | D4: =A4/$A$3 -> 1.0261054 | E4: =A4/A3 -> 1.0261054 | F4: =D4-1 -> 0.026105358 | G4: =E4-1 -> 0.026105358 | H4: 2019
A5: 18119 | B5: =A5-$A$3 -> -8568.318 | C5: =A5-A4 -> -9265 | D5: =A5/$A$3 -> 0.67893671 | E5: =A5/A4 -> 0.66166375 | F5: =D5-1 -> -0.32106329 | G5: =E5-1 -> -0.33833625 | H5: 2020
A6: 8047.984 | B6: =A6-$A$3 -> -18639.334 | C6: =A6-A5 -> -10071.016 | D6: =A6/$A$3 -> 0.30156586 | E6: =A6/A5 -> 0.44417374 | F6: =D6-1 -> -0.69843414 | G6: =E6-1 -> -0.55582626 | H6: 2021
A7: 8570.1 | B7: =A7-$A$3 -> -18117.218 | C7: =A7-A6 -> 522.116 | D7: =A7/$A$3 -> 0.32113006 | E7: =A7/A6 -> 1.0648754 | F7: =D7-1 -> -0.67886994 | G7: =E7-1 -> 0.064875377 | H7: 2022
A8: 9063.1 | B8: =A8-$A$3 -> -17624.218 | C8: =A8-A7 -> 493 | D8: =A8/$A$3 -> 0.33960325 | E8: =A8/A7 -> 1.0575256 | F8: =D8-1 -> -0.66039675 | G8: =E8-1 -> 0.057525583 | H8: 2023
A9: 8898 | B9: =A9-$A$3 -> -17789.318 | C9: =A9-A8 -> -165.1 | D9: =A9/$A$3 -> 0.33341679 | E9: =A9/A8 -> 0.98178328 | F9: =D9-1 -> -0.66658321 | G9: =E9-1 -> -0.018216725 | H9: 2024
A10: =AVERAGE(A3:A9) -> 15252.786 | B10: - | C10: =SUM(C4:C9)/(COUNT(A3:A9)-1) -> -2964.8863 | D10: - | E10: =POWER(PRODUCT(E4:E9),1/(COUNT(A3:A9)-1)) -> 0.83271792 | F10: - | G10: =E10-1 -> -0.16728208 | H10: Среднее
E11: =GEOMEAN(E4:E9) -> 0.83271792 | G11: =E11-1 -> -0.16728208
A12: Вывод: анализ динамики количества ДТП с пострадавшими на 100 тысяч автомобилей за год показывает значительные колебания. Наблюдается как существенный рост, так и значительное снижение показателя в разные периоды. Абсолютный прирост демонстрирует как положительные, так и отрицательные значения, отражая нестабильность тенденции. Темпы роста и прироста также не демонстрируют устойчивой тенденции

Sheet ПакетАнализаРегрессия
A1: ВЫВОД ИТОГОВ
A3: Регрессионная статистика
A4: Множественный R | B4: 0.14808093
A5: R-квадрат | B5: 0.021927961
A6: Нормированный R-квадрат | B6: 0.01014396
A7: Стандартная ошибка | B7: 38.339078
A8: Наблюдения | B8: 85
A10: Дисперсионный анализ
B11: df | C11: SS | D11: MS | E11: F | F11: Значимость F
A12: Регрессия | B12: 1 | C12: 2735.1983 | D12: 2735.1983 | E12: 1.8608248 | F12: 0.17621733
A13: Остаток | B13: 83 | C13: 122000.45 | D13: 1469.8849
A14: Итого | B14: 84 | C14: 124735.64
B16: Коэффициенты | C16: Стандартная ошибка | D16: t-статистика | E16: P-Значение | F16: Нижние 95% | G16: Верхние 95% | H16: Нижние 95,0% | I16: Верхние 95,0%
A17: Y-пересечение | B17: 108.90951 | C17: 5.1860813 | D17: 21.000348 | E17: 5.8421244e-35 | F17: 98.594608 | G17: 119.22442 | H17: 98.594608 | I17: 119.22442
A18: Плотность автомобильных дорог общего пользования с твердым покрытием, километров дорог на 1000 км² территории | B18: -0.013524118 | C18: 0.0099141665 | D18: -1.3641205 | E18: 0.17621733 | F18: -0.033242997 | G18: 0.0061947603 | H18: -0.033242997 | I18: 0.0061947603
A22: ВЫВОД ОСТАТКА | F22: ВЫВОД ВЕРОЯТНОСТИ
A24: Наблюдение | B24: Предсказанное Количество ДТП с пострадавшими на 100 тыс. ед. автотранспорта в январе-июне 2024 г. | C24: Остатки | D24: Стандартные остатки | F24: Персентиль | G24: Количество ДТП с пострадавшими на 100 тыс. ед. автотранспорта в январе-июне 2024 г.
A25: 1 | B25: 108.40642 | C25: 58.393582 | D25: 1.5322303 | F25: 0.58823529 | G25: 11.1
A26: 2 | B26: 107.9466 | C26: 15.153402 | D26: 0.39762079 | F26: 1.7647059 | G26: 42.5
A27: 3 | B27: 108.43752 | C27: -10.537523 | D27: -0.27650149 | F27: 2.9411765 | G27: 46.7
A28: 4 | B28: 108.85001 | C28: -21.650009 | D28: -0.56808983 | F28: 4.1176471 | G28: 49.2
A29: 5 | B29: 108.83378 | C29: -18.93378 | D29: -0.49681678 | F29: 5.2941176 | G29: 49.4
A30: 6 | B30: 107.64231 | C30: -3.2423051 | D30: -0.085077126 | F30: 6.4705882 | G30: 52.5
A31: 7 | B31: 108.85407 | C31: -1.7540661 | D31: -0.046026175 | F31: 7.6470588 | G31: 53.9
A32: 8 | B32: 108.46051 | C32: -34.660514 | D32: -0.90948164 | F32: 8.8235294 | G32: 54.2
A33: 9 | B33: 108.73641 | C33: 1.9635938 | D33: 0.05152412 | F33: 10 | G33: 65.5
A34: 10 | B34: 108.89193 | C34: -62.191934 | D34: -1.6318979 | F34: 11.176471 | G34: 65.6
A35: 11 | B35: 107.34342 | C35: 59.056578 | D35: 1.5496271 | F35: 12.352941 | G35: 65.7
A36: 12 | B36: 104.65483 | C36: 15.645173 | D36: 0.4105247 | F36: 13.529412 | G36: 66.7
... A109: 85 | B109: 100.09585 | C109: -88.995847 | D109: -2.3352247 | F109: 99.411765 | G109: 265.1

Sheet ВспомогательнаяКСводной
B2: К какому Федеральному округу принадлежит | C2: единица наблюдения, регион | D2: Количество ДТП с пострадавшими на 100 тыс. ед. автотранспорта в январе-июне 2024 г. | E2: Плотность автомобильных дорог общего пользования с твердым покрытием, километров дорог на 1000 км² территории
B3: Дальневосточный федеральный округ | C3: Амурская область | D3: 166.8 | E3: 37.2
B4: Дальневосточный федеральный округ | C4: Еврейская автономная область | D4: 123.1 | E4: 71.2
B5: Дальневосточный федеральный округ | C5: Забайкальский край | D5: 97.9 | E5: 34.9
B6: Дальневосточный федеральный округ | C6: Камчатский край | D6: 87.2 | E6: 4.4
B7: Дальневосточный федеральный округ | C7: Магаданская область | D7: 89.9 | E7: 5.6
B8: Дальневосточный федеральный округ | C8: Приморский край | D8: 104.4 | E8: 93.7
B9: Дальневосточный федеральный округ | C9: Республика Саха (Якутия) | D9: 107.1 | E9: 4.1
B10: Дальневосточный федеральный округ | C10: Сахалинская область | D10: 73.8 | E10: 33.2
B11: Дальневосточный федеральный округ | C11: Хабаровский край | D11: 110.7 | E11: 12.8
B12: Дальневосточный федеральный округ | C12: Чукотский автономный округ | D12: 46.7 | E12: 1.3
B13: Приволжский федеральный округ | C13: Кировская область | D13: 166.4 | E13: 115.8
B14: Приволжский федеральный округ | C14: Нижегородская область | D14: 120.3 | E14: 314.6
... B87: Южный федеральный округ | C87: Чеченская Республика | D87: 11.1 | E87: 651.7

Sheet АвтоматичВспомогатКРегрессии
B2: Регион | C2: Количество ДТП с пострадавшими на 100 тыс. ед. автотранспорта в январе-июне 2024 г. | D2: Плотность автомобильных дорог общего пользования с твердым покрытием, километров дорог на 1000 км² территории | E2: К какому Федеральному округу принадлежит
B3: Ярославская область | C3: 133.3 | D3: 287.1 | E3: Центральный федеральный округ
B4: Ямало-Ненецкий автономный округ | C4: 42.5 | D4: 3.7 | E4: Уральский федеральный округ
B5: Чукотский автономный округ | C5: 46.7 | D5: 1.3 | E5: Дальневосточный федеральный округ
B6: Чувашская Республика | C6: 95.1 | D6: 471.7 | E6: Приволжский федеральный округ
B7: Чеченская Республика | C7: 11.1 | D7: 651.7 | E7: Южный федеральный округ
B8: Челябинская область | C8: 96.7 | D8: 248.6 | E8: Уральский федеральный округ
B9: Ханты-Мансийский автономный округ — Югра | C9: 53.9 | D9: 11.7 | E9: Уральский федеральный округ
B10: Хабаровский край | C10: 110.7 | D10: 12.8 | E10: Дальневосточный федеральный округ
B11: Ульяновская область | C11: 88.1 | D11: 262.6 | E11: Приволжский федеральный округ
B12: Удмуртская Республика | C12: 112.8 | D12: 269.6 | E12: Приволжский федеральный округ
B13: Тюменская область | C13: 176.8 | D13: 93.2 | E13: Уральский федеральный округ
B14: Тульская область | C14: 108.6 | D14: 413.1 | E14: Центральный федеральный округ
... B87: Алтайский край | C87: 105.4 | D87: 199.8 | E87: Сибирский федеральный округ

Sheet Уравнение регрессии
C2: Уравнение регрессии:
D19: y = -1,6214x + 482,3
D20: R² = 0,0219
C21: По вертикальной оси - Плотность автомобильных дорог общего пользования с твердым покрытием, километров дорог на 1000 км² территории | D21: По горизонтальной оси - Количество ДТП с пострадавшими на 100 тыс. ед. автотранспорта в январе-июне 2024 г.
C22: Вывод: регрессионный анализ показывает слабую отрицательную корреляцию между плотностью автомобильных дорог общего пользования с твердым покрытием и количеством ДТП с пострадавшими на 100 тыс. единиц автотранспорта в январе-июне 2024 года (R² = 0,0219). Уравнение регрессии y = -1,6214x + 482,3 указывает на незначительное снижение плотности дорог с увеличением числа ДТП. Низкое значение коэффициента детерминации (R²) свидетельствует о том, что модель плохо объясняет вариативность данных, и другие факторы существенно влияют на количество ДТП. Полученные результаты не позволяют сделать однозначный вывод о прямой зависимости между плотностью дорог и числом аварий.

Sheet DPCache_Рабочая таблица
A1: Доля автомобильных дорог общего пользования регионального или межмуниципального значения и местного значения, отвечающих нормативным требованиям, в общей протяженности соответствующих дорог на конец 2023 года, %
A2: 37.2
A3: 74.9
A4: 71.3
A5: 37.3
A6: 52.2
A7: 84.1
A8: 88.4
A9: 71.4
A10: 59.7
A11: 41.9
A12: 72.8
A13: 53.9
... A86: 36.3

Sheet DPCache_Таблица с одним кач и д
A1: Регион | B1: Количество ДТП с пострадавшими на 100 тыс. ед. автотранспорта в январе-июне 2024 г. | C1: Плотность автомобильных дорог общего пользования с твердым покрытием, километров дорог на 1000 км² территории | D1: К какому Федеральному округу принадлежит
A2: Ярославская область | B2: 133.3 | C2: 287.1 | D2: Центральный федеральный округ
A3: Ямало-Ненецкий автономный округ | B3: 42.5 | C3: 3.7 | D3: Уральский федеральный округ
A4: Чукотский автономный округ | B4: 46.7 | C4: 1.3 | D4: Дальневосточный федеральный округ
A5: Чувашская Республика | B5: 95.1 | C5: 471.7 | D5: Приволжский федеральный округ
A6: Чеченская Республика | B6: 11.1 | C6: 651.7 | D6: Южный федеральный округ
A7: Челябинская область | B7: 96.7 | C7: 248.6 | D7: Уральский федеральный округ
A8: Ханты-Мансийский автономный округ — Югра | B8: 53.9 | C8: 11.7 | D8: Уральский федеральный округ
A9: Хабаровский край | B9: 110.7 | C9: 12.8 | D9: Дальневосточный федеральный округ
A10: Ульяновская область | B10: 88.1 | C10: 262.6 | D10: Приволжский федеральный округ
A11: Удмуртская Республика | B11: 112.8 | C11: 269.6 | D11: Приволжский федеральный округ
A12: Тюменская область | B12: 176.8 | C12: 93.2 | D12: Уральский федеральный округ
A13: Тульская область | B13: 108.6 | C13: 413.1 | D13: Центральный федеральный округ
... A86: Алтайский край | B86: 105.4 | C86: 199.8 | D86: Сибирский федеральный округ

Sheet DPCache_Рабочая таблица -1
A1: Регион | B1: Количество ДТП с пострадавшими на 100 тыс. ед. автотранспорта в январе-июне 2024 г. | C1: Число пострадавших (погибших и раненых) в ДТП на 100 тыс. жителей в январе-июне 2024 г. | D1: Доля автомобильных дорог общего пользования регионального или межмуниципального значения и местного значения, отвечающих нормативным требованиям, в общей протяженности соответствующих дорог на конец 2023 года, % | E1: Плотность автомобильных дорог общего пользования с твердым покрытием, километров дорог на 1000 км² территории | F1: К какому Федеральному округу принадлежит
A2: Ярославская область | B2: 133.3 | C2: 72.3 | D2: 37.2 | E2: 287.1 | F2: Центральный федеральный округ
A3: Ямало-Ненецкий автономный округ | B3: 42.5 | C3: 28.5 | D3: 74.9 | E3: 3.7 | F3: Уральский федеральный округ
A4: Чукотский автономный округ | B4: 46.7 | C4: 25 | D4: 71.3 | E4: 1.3 | F4: Дальневосточный федеральный округ
A5: Чувашская Республика | B5: 95.1 | C5: 41.9 | D5: 37.3 | E5: 471.7 | F5: Приволжский федеральный округ
A6: Чеченская Республика | B6: 11.1 | C6: 5.2 | D6: 52.2 | E6: 651.7 | F6: Южный федеральный округ
A7: Челябинская область | B7: 96.7 | C7: 59.3 | D7: 84.1 | E7: 248.6 | F7: Уральский федеральный округ
A8: Ханты-Мансийский автономный округ — Югра | B8: 53.9 | C8: 43.3 | D8: 88.4 | E8: 11.7 | F8: Уральский федеральный округ
A9: Хабаровский край | B9: 110.7 | C9: 59.9 | D9: 71.4 | E9: 12.8 | F9: Дальневосточный федеральный округ
A10: Ульяновская область | B10: 88.1 | C10: 49.5 | D10: 59.7 | E10: 262.6 | F10: Приволжский федеральный округ
A11: Удмуртская Республика | B11: 112.8 | C11: 54 | D11: 41.9 | E11: 269.6 | F11: Приволжский федеральный округ
A12: Тюменская область | B12: 176.8 | C12: 106.2 | D12: 72.8 | E12: 93.2 | F12: Уральский федеральный округ
A13: Тульская область | B13: 108.6 | C13: 67 | D13: 53.9 | E13: 413.1 | F13: Центральный федеральный округ
... A86: Алтайский край | B86: 105.4 | C86: 65.7 | D86: 36.3 | E86: 199.8 | F86: Сибирский федеральный округ

Sheet DPCache_Рабочая таблица 0
A1: Регион | B1: Количество ДТП с пострадавшими на 100 тыс. ед. автотранспорта в январе-июне 2024 г. | C1: Число пострадавших (погибших и раненых) в ДТП на 100 тыс. жителей в январе-июне 2024 г. | D1: Доля автомобильных дорог общего пользования регионального или межмуниципального значения и местного значения, отвечающих нормативным требованиям, в общей протяженности соответствующих дорог на конец 2023 года, % | E1: Плотность автомобильных дорог общего пользования с твердым покрытием, километров дорог на 1000 км² территории | F1: К какому Федеральному округу принадлежит
A2: Ярославская область | B2: 133.3 | C2: 72.3 | D2: 37.2 | E2: 287.1 | F2: Центральный федеральный округ
A3: Ямало-Ненецкий автономный округ | B3: 42.5 | C3: 28.5 | D3: 74.9 | E3: 3.7 | F3: Уральский федеральный округ
A4: Чукотский автономный округ | B4: 46.7 | C4: 25 | D4: 71.3 | E4: 1.3 | F4: Дальневосточный федеральный округ
A5: Чувашская Республика | B5: 95.1 | C5: 41.9 | D5: 37.3 | E5: 471.7 | F5: Приволжский федеральный округ
A6: Чеченская Республика | B6: 11.1 | C6: 5.2 | D6: 52.2 | E6: 651.7 | F6: Южный федеральный округ
A7: Челябинская область | B7: 96.7 | C7: 59.3 | D7: 84.1 | E7: 248.6 | F7: Уральский федеральный округ
A8: Ханты-Мансийский автономный округ — Югра | B8: 53.9 | C8: 43.3 | D8: 88.4 | E8: 11.7 | F8: Уральский федеральный округ
A9: Хабаровский край | B9: 110.7 | C9: 59.9 | D9: 71.4 | E9: 12.8 | F9: Дальневосточный федеральный округ
A10: Ульяновская область | B10: 88.1 | C10: 49.5 | D10: 59.7 | E10: 262.6 | F10: Приволжский федеральный округ
A11: Удмуртская Республика | B11: 112.8 | C11: 54 | D11: 41.9 | E11: 269.6 | F11: Приволжский федеральный округ
A12: Тюменская область | B12: 176.8 | C12: 106.2 | D12: 72.8 | E12: 93.2 | F12: Уральский федеральный округ
A13: Тульская область | B13: 108.6 | C13: 67 | D13: 53.9 | E13: 413.1 | F13: Центральный федеральный округ
... A86: Алтайский край | B86: 105.4 | C86: 65.7 | D86: 36.3 | E86: 199.8 | F86: Сибирский федеральный округ

Sheet DPCache_Рабочая таблица 1
A1: Регион | B1: Количество ДТП с пострадавшими на 100 тыс. ед. автотранспорта в январе-июне 2024 г. | C1: Число пострадавших (погибших и раненых) в ДТП на 100 тыс. жителей в январе-июне 2024 г. | D1: Доля автомобильных дорог общего пользования регионального или межмуниципального значения и местного значения, отвечающих нормативным требованиям, в общей протяженности соответствующих дорог на конец 2023 года, % | E1: Плотность автомобильных дорог общего пользования с твердым покрытием, километров дорог на 1000 км² территории | F1: К какому Федеральному округу принадлежит
A2: Ярославская область | B2: 133.3 | C2: 72.3 | D2: 37.2 | E2: 287.1 | F2: Центральный федеральный округ
A3: Ямало-Ненецкий автономный округ | B3: 42.5 | C3: 28.5 | D3: 74.9 | E3: 3.7 | F3: Уральский федеральный округ
A4: Чукотский автономный округ | B4: 46.7 | C4: 25 | D4: 71.3 | E4: 1.3 | F4: Дальневосточный федеральный округ
A5: Чувашская Республика | B5: 95.1 | C5: 41.9 | D5: 37.3 | E5: 471.7 | F5: Приволжский федеральный округ
A6: Чеченская Республика | B6: 11.1 | C6: 5.2 | D6: 52.2 | E6: 651.7 | F6: Южный федеральный округ
A7: Челябинская область | B7: 96.7 | C7: 59.3 | D7: 84.1 | E7: 248.6 | F7: Уральский федеральный округ
A8: Ханты-Мансийский автономный округ — Югра | B8: 53.9 | C8: 43.3 | D8: 88.4 | E8: 11.7 | F8: Уральский федеральный округ
A9: Хабаровский край | B9: 110.7 | C9: 59.9 | D9: 71.4 | E9: 12.8 | F9: Дальневосточный федеральный округ
A10: Ульяновская область | B10: 88.1 | C10: 49.5 | D10: 59.7 | E10: 262.6 | F10: Приволжский федеральный округ
A11: Удмуртская Республика | B11: 112.8 | C11: 54 | D11: 41.9 | E11: 269.6 | F11: Приволжский федеральный округ
A12: Тюменская область | B12: 176.8 | C12: 106.2 | D12: 72.8 | E12: 93.2 | F12: Уральский федеральный округ
A13: Тульская область | B13: 108.6 | C13: 67 | D13: 53.9 | E13: 413.1 | F13: Центральный федеральный округ
... A86: Алтайский край | B86: 105.4 | C86: 65.7 | D86: 36.3 | E86: 199.8 | F86: Сибирский федеральный округ
